Workbook
Name CÉGASZ: [1]Param!$B$7
Name CÉGASZ: [2]Param!$B$7
Name CÉGCÍM: [1]Param!$B$4
Name CÉGCÍM: [2]Param!$B$4
Name CÉGNÉV: [1]Param!$B$2
Name CÉGNÉV: [2]Param!$B$2
Name CÉGSZLA: [1]Param!$B$5
Name CÉGSZLA: [2]Param!$B$5
Name CJSZ: [1]Param!$B$6
Name CJSZ: [2]Param!$B$6
Name d: {"0";"egy";"kettő";"három";"négy";"öt";"hat";"hét";"nyolc";"kilenc"}
Name d: {"0";"egy";"kettő";"három";"négy";"öt";"hat";"hét";"nyolc";"kilenc"}
Name d: {"0";"egy";"kettő";"három";"négy";"öt";"hat";"hét";"nyolc";"kilenc"}
Name d: {"0";"egy";"kettő";"három";"négy";"öt";"hat";"hét";"nyolc";"kilenc"}
Name n_1: {"0";"egy";"kettő";"három";"négy";"öt";"hat";"hét";"nyolc";"kilenc"}
Name n_1: {"0";"egy";"kettő";"három";"négy";"öt";"hat";"hét";"nyolc";"kilenc"}
Name n_1: {"0";"egy";"kettő";"három";"négy";"öt";"hat";"hét";"nyolc";"kilenc"}
Name n_1: {"0";"egy";"kettő";"három";"négy";"öt";"hat";"hét";"nyolc";"kilenc"}
Name n_1: {"0";"egy";"kettő";"három";"négy";"öt";"hat";"hét";"nyolc";"kilenc"}
Name n_1: {"0";"egy";"kettő";"három";"négy";"öt";"hat";"hét";"nyolc";"kilenc"}
Name n_1: {"0";"egy";"kettő";"három";"négy";"öt";"hat";"hét";"nyolc";"kilenc"}
Name n_1: {"0";"egy";"kettő";"három";"négy";"öt";"hat";"hét";"nyolc";"kilenc"}
Name n_1: {"0";"egy";"kettő";"három";"négy";"öt";"hat";"hét";"nyolc";"kilenc"}
Name n_1: {"0";"egy";"kettő";"három";"négy";"öt";"hat";"hét";"nyolc";"kilenc"}
Name n_1: {"0";"egy";"kettő";"három";"négy";"öt";"hat";"hét";"nyolc";"kilenc"}
Name n_1: {"0";"egy";"kettő";"három";"négy";"öt";"hat";"hét";"nyolc";"kilenc"}
Name n_t: {"","tizen","huszon","harminc","negyven","ötven","hatvan","hetven","nyolcvan","kilencven"}
Name n_t: {"","tizen","huszon","harminc","negyven","ötven","hatvan","hetven","nyolcvan","kilencven"}
Name n_t: {"","tizen","huszon","harminc","negyven","ötven","hatvan","hetven","nyolcvan","kilencven"}
Name n_t: {"","tizen","huszon","harminc","negyven","ötven","hatvan","hetven","nyolcvan","kilencven"}
Name n_t: {"","tizen","huszon","harminc","negyven","ötven","hatvan","hetven","nyolcvan","kilencven"}
Name n_t: {"","tizen","huszon","harminc","negyven","ötven","hatvan","hetven","nyolcvan","kilencven"}
Name n_t: {"","tizen","huszon","harminc","negyven","ötven","hatvan","hetven","nyolcvan","kilencven"}
Name n_t: {"","tizen","huszon","harminc","negyven","ötven","hatvan","hetven","nyolcvan","kilencven"}
Name n_t: {"","tizen","huszon","harminc","negyven","ötven","hatvan","hetven","nyolcvan","kilencven"}
Name n_t: {"","tizen","huszon","harminc","negyven","ötven","hatvan","hetven","nyolcvan","kilencven"}
Name n_t: {"","tizen","huszon","harminc","negyven","ötven","hatvan","hetven","nyolcvan","kilencven"}
Name n_t: {"","tizen","huszon","harminc","negyven","ötven","hatvan","hetven","nyolcvan","kilencven"}

Sheet PT_BE
A1: Prompt Integra Kft. | B1: Bevételi pénztárbizonylat | D1: Sorszám: PB | E1: 01
A2: Alfonz Aladár | D2: által (megbízásából) fizetett
A3: 400000 | C3: forintot, azaz | D3: Kelt: | E3: 45933
A4: Négyszázezer | D4: forintot az alábbiak szerint bevételezni:
A5: Készpénzfor- galmi jogcím | B5: Főkönyvi számlaszám | C5: Szöveg | E5: Összeg
C6: Tőke befizetés | E6: 400000
A9: Utalványozó: | B9: Ellenőr: | D9: Összesen: | E9: =SUM(E6:E7) -> 400000
D10: Melléklet, db: | E10: 0
A11: Könyvelő: | B11: Pénztáros (Kiállító): | C11: Az összeg befizetőjének aláírása, személyi azonosító száma:
B12: Hrabovszki András | C12: Alfonz Aladár
A16: Prompt Integra Kft. | B16: Bevételi pénztárbizonylat | D16: Sorszám: PB | E16: 02
A17: Bélapátfalvi Bendegúz | D17: által (megbízásából) fizetett
A18: 400000 | C18: forintot, azaz | D18: Kelt: | E18: 45933
A19: Négyszázezer | D19: forintot az alábbiak szerint bevételezni:
A20: Készpénzfor- galmi jogcím | B20: Főkönyvi számlaszám | C20: Szöveg | E20: Összeg
C21: Tőke befizetés | E21: 400000
A24: Utalványozó: | B24: Ellenőr: | D24: Összesen: | E24: =SUM(E21:E22) -> 400000
D25: Melléklet, db: | E25: 0
A26: Könyvelő: | B26: Pénztáros (Kiállító): | C26: Az összeg befizetőjének aláírása, személyi azonosító száma:
B27: Hrabovszki András | C27: Bélapátfalvi Bendegúz
A31: Prompt Integra Kft. | B31: Bevételi pénztárbizonylat | D31: Sorszám: PB | E31: 03
A32: Cirmai Cecília | D32: által (megbízásából) fizetett
A33: 400000 | C33: forintot, azaz | D33: Kelt: | E33: 45933
A34: Négyszázezer | D34: forintot az alábbiak szerint bevételezni:
A35: Készpénzfor- galmi jogcím | B35: Főkönyvi számlaszám | C35: Szöveg | E35: Összeg
C36: Tőke befizetés | E36: 400000
A39: Utalványozó: | B39: Ellenőr: | D39: Összesen: | E39: =SUM(E36:E37) -> 400000
D40: Melléklet, db: | E40: 0
A41: Könyvelő: | B41: Pénztáros (Kiállító): | C41: Az összeg befizetőjének aláírása, személyi azonosító száma:
B42: Hrabovszki András | C42: Cirmai Cecília
A45: Prompt Integra Kft. | B45: Bevételi pénztárbizonylat | D45: Sorszám: PB | E45: 04
A46: Hrabovszki András | D46: által (megbízásából) fizetett
A47: 400000 | C47: forintot, azaz | D47: Kelt: | E47: 45933
A48: Négyszázezer | D48: forintot az alábbiak szerint bevételezni:
A49: Készpénzfor- galmi jogcím | B49: Főkönyvi számlaszám | C49: Szöveg | E49: Összeg
C50: Tőke befizetés | E50: 400000
A53: Utalványozó: | B53: Ellenőr: | D53: Összesen: | E53: =SUM(E50:E51) -> 400000
D54: Melléklet, db: | E54: 0
A55: Könyvelő: | B55: Pénztáros (Kiállító): | C55: Az összeg befizetőjének aláírása, személyi azonosító száma:
B56: Hrabovszki András | C56: Hrabovszki András
...

Sheet PT_KI
A1: Prompt Integra Kft. | B1: Kiadási pénztárbizonylat | D1: Sorszám: PK | E1: 01
A2: Varga Béla | D2: részére kifizetett
A3: 84835 | C3: forintot, azaz | D3: Kelt: | E3: 45933
A4: Nyolcvannégyezer-nyolcszázharmincöt | D4: forintot az alábbiak szerint kiadásolni:
A5: Készpénzfor- galmi jogcím | B5: Főkönyvi számlaszám | C5: Szöveg | E5: Összeg
C6: Címfestő szolgáltatás (WE411/25) | E6: 84836
C7: Kerekítési különbözet | E7: -1
A9: Utalványozó: | B9: Ellenőr: | D9: Összesen: | E9: =SUM(E6:E7) -> 84835
D10: Melléklet, db: | E10: 1
A11: Könyvelő: | B11: Pénztáros (Kiállító): | C11: Az összeg átvevőjének aláírása, személyi azonosító száma:
A12: Hrabovszki András | B12: Hrabovszki András | C12: Varga Béla (444555AA)
A17: Prompt Integra Kft. | B17: Kiadási pénztárbizonylat | D17: Sorszám: PK | E17: 02
A18: Papirex Kft. | D18: részére kifizetett
A19: 5545 | C19: forintot, azaz | D19: Kelt: | E19: 45933
A20: Ötezer-ötszáznegyvenöt | D20: forintot az alábbiak szerint kiadásolni:
A21: Készpénzfor- galmi jogcím | B21: Főkönyvi számlaszám | C21: Szöveg | E21: Összeg
C22: Nyomtatványok(KR12/2025) | E22: 5547
C23: Kerekítés | E23: -2
A25: Utalványozó: | B25: Ellenőr: | D25: Összesen: | E25: =SUM(E22:E23) -> 5545
D26: Melléklet, db: | E26: 1
A27: Könyvelő: | B27: Pénztáros (Kiállító): | C27: Az összeg átvevőjének aláírása, személyi azonosító száma:
A28: Hrabovszki András | B28: Hrabovszki András | C28: Papirex Kft.
A31: Prompt Integra Kft. | B31: Kiadási pénztárbizonylat | D31: Sorszám: PK | E31: 03
A32: PénzGyűjtő Bank | D32: részére kifizetett
A33: 1600000 | C33: forintot, azaz | D33: Kelt: | E33: 45933
A34: Egymillió-hatszázezer | D34: forintot az alábbiak szerint kiadásolni:
A35: Készpénzfor- galmi jogcím | B35: Főkönyvi számlaszám | C35: Szöveg | E35: Összeg
C36: Törzsbetét befizetés (PK/48/2025) | E36: 1600000
A39: Utalványozó: | B39: Ellenőr: | D39: Összesen: | E39: =SUM(E36:E37) -> 1600000
D40: Melléklet, db: | E40: 1
A41: Könyvelő: | B41: Pénztáros (Kiállító): | C41: Az összeg átvevőjének aláírása, személyi azonosító száma:
A42: Hrabovszki András | B42: Hrabovszki András | C42: PénzGyűjtő Bank
A45: Prompt Integra Kft. | B45: Kiadási pénztárbizonylat | D45: Sorszám: PK | E45: 04
A46: Nyomtatványforgalmazó Bt. | D46: részére kifizetett
A47: 1395 | C47: forintot, azaz | D47: Kelt: | E47: 45950
A48: Ezerháromszázkilencvenöt | D48: forintot az alábbiak szerint kiadásolni:
A49: Készpénzfor- galmi jogcím | B49: Főkönyvi számlaszám | C49: Szöveg | E49: Összeg
C50: Nyomtatványok (PK/2-2025) | E50: 1397
C51: Kerekítés | E51: -2
A53: Utalványozó: | B53: Ellenőr: | D53: Összesen: | E53: =SUM(E50:E51) -> 1395
...

Sheet Jelentés_Előtársaság
A1: Cég neve: | C1: Prompt Integra Kft. | E1: Időszak: | F1: =IF(COUNTA(B6:B55)<>0,MIN(B6:B55),"") -> 45933 | G1: =IF(COUNTA(B6:B55)<>0,MAX(B6:B55),"") -> 45951
A2: Pénztár megnevezése: | C2: Házi pénztár | E2: pénztár | F2: Sorszám: | G2: PJ01
A3: Sor- szám | B3: Be-, kifizetés napja | C3: Bevételi<<<<<< | D3: Szöveg | E3: Bevétel | F3: Kiadás | G3: Napi egyenleg
C4: >>>>>>>Kiadási
C5: bizonylat sz. | E5: Ft | F5: Ft | G5: Ft
A6: 1. | B6: 45933 | C6: PB01 | D6: Tőke befizetés | E6: 400000 | G6: =E57+E6-F6 -> 400000
A7: 2. | B7: 45933 | C7: PB02 | D7: Tőke befizetés | E7: 400000 | G7: =G6+E7-F7 -> 800000
A8: 3. | B8: 45933 | C8: PB03 | D8: Tőke befizetés | E8: 400000 | G8: =G7+E8-F8 -> 1200000
A9: 4. | B9: 45933 | C9: PB04 | D9: Tőke befizetés | E9: 400000 | G9: =G8+E9-F9 -> 1600000
A10: 5. | B10: 45933 | C10: PB05 | D10: Tagi kölcsön | E10: 90380 | G10: =G9+E10-F10 -> 1690380
A11: 6. | B11: 45933 | C11: PK01 | D11: Címfestő szolgáltatás (WE411/25) | F11: 84835 | G11: =G10+E11-F11 -> 1605545
A12: 7. | B12: 45933 | C12: PK02 | D12: Nyomtatványok(KR12/2025) | F12: 5545 | G12: =G11+E12-F12 -> 1600000
A13: 8. | B13: 45933 | C13: PK03 | D13: Törzsbetét befizetés (PK/48/2025) | F13: 1600000 | G13: =G12+E13-F13 -> 0
A14: 9. | B14: 45950 | C14: PB06 | D14: Tagi Kölcsön | E14: 1395 | G14: =G13+E14-F14 -> 1395
A15: 10. | B15: 45950 | C15: PK04 | D15: Nyomtatványok (PK/2-2025) | F15: 1395 | G15: =G14+E15-F15 -> 0
A16: 11. | B16: 45951 | C16: PB07 | D16: Pénzfelvétel bankszámláról (TP425) | E16: 150000 | G16: =G15+E16-F16 -> 150000
A17: 12. | B17: 45951 | C17: PK05 | D17: Cannon 5L tintasugaras nyomtató (HY986/2025) | F17: 105105 | G17: =G16+E17-F17 -> 44895
A18: 13. | G18: =G17+E18-F18 -> 44895
A19: 14. | G19: =G18+E19-F19 -> 44895
A20: 15. | G20: =G19+E20-F20 -> 44895
A21: 16. | G21: =G20+E21-F21 -> 44895
A22: 17. | G22: =G21+E22-F22 -> 44895
A23: 18. | G23: =G22+E23-F23 -> 44895
A24: 19. | G24: =G23+E24-F24 -> 44895
A25: 20. | G25: =G24+E25-F25 -> 44895
A26: 21. | G26: =G25+E26-F26 -> 44895
A27: 22. | G27: =G26+E27-F27 -> 44895
A28: 23. | G28: =G27+E28-F28 -> 44895
A29: 24. | G29: =G28+E29-F29 -> 44895
... A41: 36. | G41: =G40+E41-F41 -> 44895
A42: 37. | G42: =G41+E42-F42 -> 44895 | I42: =A1 -> Cég neve:
A43: 38. | G43: =G42+E43-F43 -> 44895 | I43: ="Címletjegyzék " -> Címletjegyzék
A44: 39. | G44: =G43+E44-F44 -> 44895 | I44: Címlet | J44: Darab | K44: Összesen
A45: 40. | G45: =G44+E45-F45 -> 44895 | I45: 20000 | K45: =I45*J45 -> 0
A46: 41. | G46: =G45+E46-F46 -> 44895 | I46: 10000 | K46: =I46*J46 -> 0
A47: 42. | G47: =G46+E47-F47 -> 44895 | I47: 5000 | K47: =I47*J47 -> 0
A48: 43. | G48: =G47+E48-F48 -> 44895 | I48: 2000 | K48: =I48*J48 -> 0
A49: 44. | G49: =G48+E49-F49 -> 44895 | I49: 1000 | K49: =I49*J49 -> 0
A50: 45. | G50: =G49+E50-F50 -> 44895 | I50: 500 | K50: =I50*J50 -> 0
A51: 46. | G51: =G50+E51-F51 -> 44895 | I51: 200 | K51: =I51*J51 -> 0
...

Sheet Jelentés_1
A1: Cég neve: | C1: Prompt Integra Kft. | E1: Időszak: | F1: =IF(COUNTA(B6:B55)<>0,MIN(B6:B55),"") -> 45975 | G1: =IF(COUNTA(B6:B55)<>0,MAX(B6:B55),"") -> 45975
A2: Pénztár megnevezése: | C2: Házi pénztár | E2: pénztár | F2: Sorszám: | G2: PJ02
A3: Sor- szám | B3: Be-, kifizetés napja | C3: Bevételi<<<<<< | D3: Szöveg | E3: Bevétel | F3: Kiadás | G3: Napi egyenleg
C4: >>>>>>>Kiadási
C5: bizonylat sz. | E5: Ft | F5: Ft | G5: Ft
A6: 1. | B6: 45975 | C6: PK06 | D6: SZGK átírás | F6: 22000 | G6: =E57+E6-F6 -> 22895
A7: 2. | B7: 45975 | C7: PK07 | D7: Felelősségbiztosítás | F7: 22100 | G7: =G6+E7-F7 -> 795
A8: 3. | G8: =G7+E8-F8 -> 795
A9: 4. | G9: =G8+E9-F9 -> 795
A10: 5. | G10: =G9+E10-F10 -> 795
A11: 6. | G11: =G10+E11-F11 -> 795
A12: 7. | G12: =G11+E12-F12 -> 795
A13: 8. | G13: =G12+E13-F13 -> 795
A14: 9. | G14: =G13+E14-F14 -> 795
A15: 10. | G15: =G14+E15-F15 -> 795
A16: 11. | G16: =G15+E16-F16 -> 795
A17: 12. | G17: =G16+E17-F17 -> 795
A18: 13. | G18: =G17+E18-F18 -> 795
A19: 14. | G19: =G18+E19-F19 -> 795
... A41: 36. | G41: =G40+E41-F41 -> 795
A42: 37. | G42: =G41+E42-F42 -> 795 | I42: =A1 -> Cég neve:
A43: 38. | G43: =G42+E43-F43 -> 795 | I43: ="Címletjegyzék " -> Címletjegyzék
A44: 39. | G44: =G43+E44-F44 -> 795 | I44: Címlet | J44: Darab | K44: Összesen
A45: 40. | G45: =G44+E45-F45 -> 795 | I45: 20000 | K45: =I45*J45 -> 0
A46: 41. | G46: =G45+E46-F46 -> 795 | I46: 10000 | K46: =I46*J46 -> 0
A47: 42. | G47: =G46+E47-F47 -> 795 | I47: 5000 | K47: =I47*J47 -> 0
A48: 43. | G48: =G47+E48-F48 -> 795 | I48: 2000 | K48: =I48*J48 -> 0
A49: 44. | G49: =G48+E49-F49 -> 795 | I49: 1000 | K49: =I49*J49 -> 0
A50: 45. | G50: =G49+E50-F50 -> 795 | I50: 500 | K50: =I50*J50 -> 0
A51: 46. | G51: =G50+E51-F51 -> 795 | I51: 200 | K51: =I51*J51 -> 0
A52: 47. | G52: =G51+E52-F52 -> 795 | I52: 100 | K52: =I52*J52 -> 0
A53: 48. | G53: =G52+E53-F53 -> 795 | I53: 50 | K53: =I53*J53 -> 0
A54: 49. | G54: =G53+E54-F54 -> 795 | I54: 20 | K54: =I54*J54 -> 0
A55: 50. | G55: =G54+E55-F55 -> 795 | I55: 10 | K55: =I55*J55 -> 0
A56: Forgalom, Átvitel: | E56: =SUM(E6:E55) -> 0 | F56: =SUM(F6:F55) -> 44100 | I56: 5 | K56: =I56*J56 -> 0
A57: Kezdő pénzkészlet: | E57: 44895 | I57: Összesen: | K57: =SUM(K45:K56) -> 0
A58: Záró pénzkészlet nyilvántartás szerint: | F58: =E56+E57-F56 -> 795 | I58: Mellékletek:
A59: Pénzkészlet leltározás szerint: | F59: =K57 -> 0 | I59: Bevételi: | K59: db
A60: Hiány/többlet: | E60: =IF(F59>F58,F59-F58,0) -> 0 | F60: =IF(F59<F58,-F59+F58,0) -> 795 | I60: Kiadási: | K60: db
A61: Ellenőrző összesen: | E61: =E56+E57+E60 -> 44895 | F61: =F56+F58+F60 -> 45690 | I61: Összesen: | J61: =SUM(J59:J60) -> 0 | K61: db
...

Sheet Szigszam
A1: Cég neve: | B1: Prompt Integra Kft. | C1: Szigorú számadású bizonylatok analitikája | K1: Oldalszám: | L1: 1
A3: Sorszám | B3: Nyomtatvány jele, számjele, neve | C3: Sorszámtól | D3: Sorszámig | E3: Beszerzési hely (kereskedő neve) | F3: Beszerzési bizonylat száma | G3: Beszerzés dátuma | H3: Használatba vétel dátuma | I3: Felhasználás dátuma | J3: Selejtezés dátuma | K3: Tárolási hely, Megjegyzés | L3: Bejegyző neve
A4: 1. | B4: Kiadási pénztárbizonylat | C4: PK01 | D4: PK25 | E4: Papirex Kft | F4: KR12/2025 | G4: 45933 | H4: 45933 | K4: 1058 Budapest, Fővám tér 8. | L4: Hrabovszki András
A5: 2. | B5: Bevételi pénztárbizonylat | C5: PB01 | D5: PB25 | E5: Papirex Kft | F5: KR12/2026 | G5: 45933 | H5: 45933 | K5: 1058 Budapest, Fővám tér 8. | L5: Hrabovszki András
A6: 3. | B6: Szigorú számadású nyilvántartás | C6: SZ01 | D6: SZ01 | E6: Papirex Kft | F6: KR12/2027 | G6: 45933 | H6: 45933 | K6: 1058 Budapest, Fővám tér 8. | L6: Hrabovszki András
A7: 4. | B7: Pénztárjelentés nyomtatványtömb | C7: PJ01 | D7: PJ020 | E7: Nyomtatványforgalmazó Bt. | F7: PK/2-2025 | G7: 45950 | H7: 45950 | K7: 1058 Budapest, Fővám tér 8. | L7: Hrabovszki András
A8: 5. | B8: 100 l számlatömb | C8: RL-791001 | D8: RL11000 | E8: Nyomtatványforgalmazó Bt. | F8: PK/2-2025 | G8: 45950 | H8: 45950 | K8: 1058 Budapest, Fővám tér 8. | L8: Hrabovszki András
A9: 6.
A10: 7.
A11: 8.
A12: 9.
A13: 10.
A14: 11.
A15: 12.
A16: 13.
A17: 14.
A18: 15.
A19: 16.
A20: 17.
A21: 18.
B23: Utolsó bejegyzés:
B24: Ellenőrizve:
B25: Ellenőr neve:

Sheet Utalas
B1: PénzGyűjtő Bank | G1: PGy
B2: 1033 Budapest, Kézműves u. 3.
B3: Pénzgyűjtő direkt: 06-40-571111
B5: Átutalási megbízás
F6: Terhelési nap: | G6: 45946
B8: Fizető fél neve: | F8: Prompt Integra Kft.
B9: Fizető fél pénzforgalmi jelzőszáma: | F9: 15151515-23232323-46464646
B11: Kedvezményezett neve: | F11: Group Media Ügynökség
B12: Kedvezményezett pénzforgalmi jelzőszáma: | F12: 24242424-35353535-00000000
B13: Átutalás összege forintban: | F13: 304800
B15: Közlemény:
B16: Reklámfelület bérbeadás ( JJ8821/2025.)
B18: A megbízás kelte: | C18: 2025.10.16 | F18: Aláírás: | G18: Alfonz Aladár

Sheet Utalas (2)
B1: PénzGyűjtő Bank | G1: PGy
B2: 1033 Budapest, Kézműves u. 3.
B3: Pénzgyűjtő direkt: 06-40-571111
B5: Átutalási megbízás
F6: Terhelési nap: | G6: 45966
B8: Fizető fél neve: | F8: Prompt Integra Kft.
B9: Fizető fél pénzforgalmi jelzőszáma: | F9: 15151515-23232323-46464646
B11: Kedvezményezett neve: | F11: Villa Star Nyrt.
B12: Kedvezményezett pénzforgalmi jelzőszáma: | F12: 56789320-41236589-78965412
B13: Átutalás összege forintban: | F13: =7932674-396634 -> 7536040
B15: Közlemény:
B16: Fényzáró roló és szalagfüggöny vásárlás ( OK1214/25)
B18: A megbízás kelte: | C18: 2025.11.05 | F18: Aláírás: | G18: Alfonz Aladár

Sheet Utalas (3)
B1: PénzGyűjtő Bank | G1: PGy
B2: 1033 Budapest, Kézműves u. 3.
B3: Pénzgyűjtő direkt: 06-40-571111
B5: Átutalási megbízás
F6: Terhelési nap: | G6: 45983
B8: Fizető fél neve: | F8: Prompt Integra Kft.
B9: Fizető fél pénzforgalmi jelzőszáma: | F9: 15151515-23232323-46464646
B11: Kedvezményezett neve: | F11: Poly Groupo Zrt.
B12: Kedvezményezett pénzforgalmi jelzőszáma: | F12: 64793182-58963214-74125896
B13: Átutalás összege forintban: | F13: 1778000
B15: Közlemény:
B16: Személygépjármű vásárlás ( HT556/2025.)
B18: A megbízás kelte: | C18: 2025.11.22 | F18: Aláírás: | G18: Alfonz Aladár

Sheet Kimenő számla
A1: Számla
A2: A számlakibocsátó neve, címe, adóigazgatási azonosítója: | B2: Vevő neve, címe, adóigazgatási azonosítója:
A3: Prompt Integra Kft. | B3: General Architect Nyrt.
A4: 1058 Budapest, Fővám tér 8. | B4: 1011 Budapest, Árpád fejedelem útja 2., adószám: 15111212-2-51
A5: 01-09-200100 | B5: Fizetési mód: | D5: Teljesítés időpontja: | E5: Számla kelte: | F5: Fizetés határideje: | H5: Számla száma:
A6: 15151515-23232323-46464646 | B6: Átutalás | D6: 45951 | E6: 45951 | F6: 45967 | H6: RL-791001
A8: Termék vagy szolgáltatás megnevezése: | B8: Menny. egység | C8: Mennyiség | D8: Egységár (ÁFA nélkül) | E8: Értéke ÁFA nélkül | F8: ÁFA kulcs | G8: Áthárított ÁFA | H8: Ellenérték ÁFÁ-val
A9: Árnyékolás technikai szakértői szolgáltatás | B9: alkalom | C9: 1 | D9: 3600000 | E9: =C9*D9 -> 3600000 | F9: 0.27 | G9: =E9*F9 -> 972000 | H9: =E9+G9 -> 4572000
A14: Végösszeg: | E14: =SUM(E9:E13) -> 3600000 | G14: =SUM(G9:G13) -> 972000 | H14: =SUM(H9:H13) -> 4572000
A16: A számlában szereplő ÁFA részletezése | D16: 0.27 | E16: 0.05 | F16: TAM | H16: Összesen:
A17: Számlaérték ÁFA nélkül | D17: =SUM(E9:E13) -> 3600000 | E17: 0 | F17: 0 | H17: =SUM(D17:G17) -> 3600000
A18: ÁFA összege | D18: =SUM(G9:G10) -> 972000 | E18: 0 | F18: 0 | H18: =SUM(D18:G18) -> 972000
A19: A számla végösszege | D19: =SUM(D17:D18) -> 4572000 | E19: =SUM(E17:E18) -> 0 | F19: =SUM(F17:G18) -> 0 | H19: =SUM(H17:H18) -> 4572000

Sheet Kimenő számla (2)
A1: Számla
A2: A számlakibocsátó neve, címe, adóigazgatási azonosítója: | B2: Vevő neve, címe, adóigazgatási azonosítója:
A3: Prompt Integra Kft. | B3: General Architect Nyrt.
A4: 1058 Budapest, Fővám tér 8. | B4: 1011 Budapest, Árpád fejedelem útja 2., adószám: 15111212-2-51
A5: 01-09-200100 | B5: Fizetési mód: | D5: Teljesítés időpontja: | E5: Számla kelte: | F5: Fizetés határideje: | H5: Számla száma:
A6: 15151515-23232323-46464646 | B6: Átutalás | D6: 45952 | E6: 45952 | F6: 45967 | H6: RL-791002
A8: Termék vagy szolgáltatás megnevezése: | B8: Menny. egység | C8: Mennyiség | D8: Egységár (ÁFA nélkül) | E8: Értéke ÁFA nélkül | F8: ÁFA kulcs | G8: Áthárított ÁFA | H8: Ellenérték ÁFÁ-val
A9: Előlegfizetés, árnyékolásitechnikai elemek | B9: db | C9: 1 | D9: =400000/1.27 -> 314960.63 | E9: =C9*D9 -> 314960.63 | F9: 0.27 | G9: =E9*F9 -> 85039.37 | H9: =E9+G9 -> 400000
A14: Végösszeg: | E14: =SUM(E9:E13) -> 314960.63 | G14: =SUM(G9:G13) -> 85039.37 | H14: =SUM(H9:H13) -> 400000
A16: A számlában szereplő ÁFA részletezése | D16: 0.27 | E16: 0.05 | F16: TAM | H16: Összesen:
A17: Számlaérték ÁFA nélkül | D17: =SUM(E9:E13) -> 314960.63 | E17: 0 | F17: 0 | H17: =SUM(D17:G17) -> 314960.63
A18: ÁFA összege | D18: =SUM(G9:G10) -> 85039.37 | E18: 0 | F18: 0 | H18: =SUM(D18:G18) -> 85039.37
A19: A számla végösszege | D19: =SUM(D17:D18) -> 400000 | E19: =SUM(E17:E18) -> 0 | F19: =SUM(F17:G18) -> 0 | H19: =SUM(H17:H18) -> 400000

Sheet Kimenő számla (3)
A1: Számla
A2: A számlakibocsátó neve, címe, adóigazgatási azonosítója: | B2: Vevő neve, címe, adóigazgatási azonosítója:
A3: Prompt Integra Kft. | B3: General Architect Nyrt.
A4: 1058 Budapest, Fővám tér 8. | B4: 1011 Budapest, Árpád fejedelem útja 2., adószám: 15111212-2-51
A5: 01-09-200100 | B5: Fizetési mód: | D5: Teljesítés időpontja: | E5: Számla kelte: | F5: Fizetés határideje: | H5: Számla száma:
A6: 15151515-23232323-46464646 | B6: Átutalás | D6: 45975 | E6: 45975 | F6: 45990 | H6: RL-791003
A8: Termék vagy szolgáltatás megnevezése: | B8: Menny. egység | C8: Mennyiség | D8: Egységár (ÁFA nélkül) | E8: Értéke ÁFA nélkül | F8: ÁFA kulcs | G8: Áthárított ÁFA | H8: Ellenérték ÁFÁ-val
A9: Fényzáró roló | B9: db | C9: 32 | D9: 153200 | E9: =C9*D9 -> 4902400 | F9: 0.27 | G9: =E9*F9 -> 1323648 | H9: =E9+G9 -> 6226048
A10: Szalagfüggöny | B10: db | C10: 11 | D10: 111300 | E10: =C10*D10 -> 1224300 | F10: 0.27 | G10: =E10*F10 -> 330561 | H10: =E10+G10 -> 1554861 | J10: =SUM(G9:G10) -> 1654209
A11: Előleg (RL-791002) | B11: eset | C11: 1 | D11: =-'Kimenő számla (2)'!D9 -> -314960.63 | E11: =-'Kimenő számla (2)'!E9 -> -314960.63 | F11: 0.27 | G11: =-'Kimenő számla (2)'!G9 -> -85039.37 | H11: =-'Kimenő számla (2)'!H9 -> -400000
A14: Végösszeg: | E14: =SUM(E9:E13) -> 5811739.4 | G14: =SUM(G9:G13) -> 1569169.6 | H14: =SUM(H9:H13) -> 7380909
A16: A számlában szereplő ÁFA részletezése | D16: 0.27 | E16: 0.05 | F16: TAM | H16: Összesen:
A17: Számlaérték ÁFA nélkül | D17: =SUM(E9:E13) -> 5811739.4 | E17: 0 | F17: 0 | H17: =SUM(D17:G17) -> 5811739.4
A18: ÁFA összege | D18: =SUM(G9:G11) -> 1569169.6 | E18: 0 | F18: 0 | H18: =SUM(D18:G18) -> 1569169.6
A19: A számla végösszege | D19: =SUM(D17:D18) -> 7380909 | E19: =SUM(E17:E18) -> 0 | F19: =SUM(F17:G18) -> 0 | H19: =SUM(H17:H18) -> 7380909

Sheet Folyószámla analitika
A1: Folyószámla analitika
A2: Sorszám | B2: Vevő/Szállító | C2: Partner | D2: Esemény | E2: Számlaszám | F2: Bankszámlaszáma | G2: Számla kelte | H2: Fizetési határidő | I2: Kifizetés dátuma | J2: Számla végösszege | K2: Kiegyenlített összeg | L2: Fennmaradó összeg
A3: 1 | B3: Szállító | C3: Varga Tekla egyéni ügyvéd | D3: Alapítás | E3: UJ44/2025 | F3: 57595351-69874123 | G3: 45933 | H3: 45963 | J3: 186340 | K3: 0 | L3: =J3-K3 -> 186340
A4: 2 | B4: Szállító | C4: Group Media Ügynökség | D4: Reklám felületbérlés | E4: UZ119/2025 | F4: 24242424-35353535 | G4: 45938 | H4: 45946 | I4: 45946 | J4: 304800 | K4: 304800 | L4: =J4-K4 -> 0
A5: 3 | B5: Szállító | C5: StarSite Group Kft. | D5: Webes szolgáltatás | E5: JJ8821/2025 | F5: 85858585-76767676-45454545 | G5: 45943 | H5: 45958 | J5: 152400 | K5: 152400 | L5: =J5-K5 -> 0
A6: 4 | B6: Vevő | C6: General Architect Nyrt. | D6: Tanácsadói szolgáltatás | E6: RL-791001 | G6: 45951 | H6: 45967 | I6: 45966 | J6: 4572000 | K6: 4572000 | L6: =J6-K6 -> 0
A7: 5 | B7: Vevő | C7: General Architect Nyrt. | D7: Előlegfizetés, árnyékolásitechnikai elemek | E7: RL-791002 | G7: 45951 | H7: 45967 | I7: 45960 | J7: 400000 | K7: 400000 | L7: =J7-K7 -> 0
A8: 6 | B8: Szállító | C8: Villa Star Nyrt. | D8: Fényzáró roló és szalagfüggöny | E8: OK1214/25 | F8: 56789320-41236589-78965412 | G8: 45966 | H8: 45974 | I8: 45968 | J8: =7932674-396634 -> 7536040 | K8: 7536040 | L8: =J8-K8 -> 0
A9: 7 | B9: Szállító | C9: Poly Groupo Zrt. | D9: Személygépjármű vásárlás | E9: HT556/2025. | F9: 64793182-58963214-74125896 | G9: 45975 | H9: 45983 | I9: 45985 | J9: 1778000 | K9: 1778000 | L9: =J9-K9 -> 0
A10: 8 | B10: Vevő | C10: General Architect Nyrt. | D10: Szalagfüggöny és roló vásárlás | E10: RL-791003 | G10: 45975 | H10: 45990 | J10: ='Kimenő számla (3)'!H14 -> 7380909 | K10: 0 | L10: =J10-K10 -> 7380909

Sheet ÁFA  analitika
A1: Áfa analitika
A2: Bizonylatszám | B2: Tétel | C2: Partner neve | D2: Előzetesen felszámított/ Fizetendő áfa | E2: Levonható/ Nem levonható áfa | F2: Áfabevallás száma | G2: Számla kelte | H2: adó alapja | I2: Áfa kulcs | J2: Áfa összege | K2: Áfa teljesítés időpontja | L2: Speciális
A3: WE411/25 | B3: Címfestő szolgáltatás | C3: Varga Béla | D3: Előzetesen felszámított áfa | E3: Levonható | F3: Előtársaság | G3: 45933 | H3: =84836/1.27 -> 66800 | I3: 0.27 | J3: =I3*H3 -> 18036
A4: KR12/2025 | B4: Nyomtatványok | C4: Papirex Kft. | D4: Előzetesen felszámított áfa | E4: Levonható | F4: Előtársaság | G4: 45933 | H4: 4368 | I4: 0.27 | J4: =I4*H4 -> 1179.36
A5: UJ44/2025 | B5: Cégalapítás díja + Sikerdíj | C5: Varga Tekla egyéni ügyvéd | D5: Előzetesen felszámított áfa | E5: Levonható | F5: Előtársaság | G5: 45933 | H5: 142000 | I5: 0.27 | J5: =I5*H5 -> 38340
A6: UZ119/2025. | B6: Reklámfelület bérbeadás | C6: Group Media Ügynökség | D6: Előzetesen felszámított áfa | E6: Levonható | F6: Előtársaság | G6: 45938 | H6: 240000 | I6: 0.27 | J6: =I6*H6 -> 64800
A7: JJ8821/2025. | B7: WebHosting szolgáltatás | C7: StarSite Group Kft. | D7: Előzetesen felszámított áfa | E7: Levonható | F7: Előtársaság | G7: 45943 | H7: 120000 | I7: 0.27 | J7: =I7*H7 -> 32400
A8: PK/2-2025. | B8: Nyomtatványok | C8: Nyomtatványforgalmazó Bt. | D8: Előzetesen felszámított áfa | E8: Levonható | F8: Előtársaság | G8: 45950 | H8: 1100 | I8: 0.27 | J8: =I8*H8 -> 297
A9: HY986/2025. | B9: Cannon 5L tintasugaras nyomtató | C9: Irodaszer-ellátó Kft. | D9: Előzetesen felszámított áfa | E9: Levonható | F9: Előtársaság | G9: 45951 | H9: 82760 | I9: 0.27 | J9: =I9*H9 -> 22345.2 | L9: TE
A10: RL-791001 | B10: Árnyékolás technikai szakértői szolgáltatás | C10: General Architect Nyrt. | D10: Fizetendő áfa | E10: - | F10: Előtársaság | G10: 45951 | H10: 3600000 | I10: 0.27 | J10: =I10*H10 -> 972000
A11: RL-791002 | B11: Előlegfizetés, árnyékolásitechnikai elemek | C11: General Architect Nyrt. | D11: Fizetendő áfa | E11: - | F11: 1 | G11: 45960 | H11: =400000/1.27 -> 314960.63 | I11: 0.27 | J11: =I11*H11 -> 85039.37
A12: HZ-7127 | B12: Számítógép, OEM, Monitor | C12: Műszerház Kft. | D12: Előzetesen felszámított áfa | E12: Levonható | F12: 1 | G12: 45960 | H12: 321200 | I12: 0.27 | J12: =I12*H12 -> 86724 | L12: TE
A13: OK1214/25 | B13: Áruvásárlás | C13: Villa Star Nyrt. | D13: Előzetesen felszámított áfa | E13: Levonható | F13: 1 | G13: 45966 | H13: 6246200 | I13: 0.27 | J13: =I13*H13 -> 1686474
A14: RL-791003 | B14: Szalagfüggöny és roló vásárlás | C14: General Architect Nyrt. | D14: Fizetendő áfa | E14: - | F14: 1 | G14: 45975 | H14: =SUM('Kimenő számla (3)'!E9:E11) -> 5811739.4 | I14: 0.27 | J14: =I14*H14 -> 1569169.6
G17: fizetendő | H17: =J11 -> 85039.37
G18: előzetesen | H18: =J12 -> 86724
H19: =H18-H17 -> 1684.6299

Sheet Főkönyvi bizonylatok
A1: Főkönyvi bizonylatok
A2: Sorszám | B2: Dátum | C2: Megnevezés | D2: Tartozik számla | E2: Követel számla | F2: Összeg
A3: KR01 | B3: 45952 | C3: Jegyzett tőke előírás | D3: 412. Jegyzett, de még be nem fizetett tőke (-) | E3: 411. Jegyzett tőke | F3: 3.200.000
A4: KR02 | B4: 45952 | C4: Előzetes felszámított áfa átvezetése (előtársaság) | D4: 4663. ÁFA átvezetési számla | E4: 4661. Előzetes ÁFA | F4: 177397
A5: KR03 | B5: 45952 | C5: Fizetendő áfa átvezetése (előtársaság) | D5: 4662. Fizetendő ÁFA | E5: 4663. ÁFA átvezetési számla | F5: 972000
A6: KR04 | B6: 45952 | C6: Áfa pénzügyi rendezése (előtársaság) | D6: 869. Különféle egyéb ráfordítások | E6: 4663. ÁFA átvezetési számla | F6: 397
A7: KR05 | B7: 45961 | C7: Előzetes felszámított áfa átvezetése (előtársaság) | D7: 4663. ÁFA átvezetési számla | E7: 4661. Előzetes ÁFA | F7: 86724
A8: KR06 | B8: 45961 | C8: Fizetendő áfa átvezetése (előtársaság) | D8: 4662. Fizetendő ÁFA | E8: 4663. ÁFA átvezetési számla | F8: 85039
A9: KR07 | B9: 45961 | C9: Áfa pénzügyi rendezése (előtársaság) | D9: 4663. ÁFA átvezetési számla | E9: 969. Különféle egyéb bevételek | F9: 315
A10: KR08 | B10: 45952 | C10: Nyomtató aktiválása | D10: 1231. Egyéb berendezések, felszerelések, járművek bruttó értéke | E10: 1251. Beruházások, felújítások bruttó értéke | F10: 82760
A11: KR09 | B11: 45952 | C11: Nyomtató écs elszámolása | D11: 53. Értékcsökkenési leírás | E11: 1232. Egyéb berendezések, felszerelések, járművek terv sz. értékcsökkenése | F11: =F10 -> 82760
A12: KR10 | B12: 45991 | C12: AA-Bruttó bér november | D12: 521. Bérköltség | E12: 4581. Jövedelem elsz. számla | F12: 200000
A13: KR11 | B13: 45991 | C13: AA-SZJA november | D13: 4581. Jövedelem elsz. számla | E13: 461103. SZJA | F13: 30000
A14: KR12 | B14: 45991 | C14: AA-TB november | D14: 4581. Jövedelem elsz. számla | E14: 461125. Társadalombiztosítási járulék | F14: 37000
A15: KR13 | B15: 45991 | C15: AA-SZOCHO november | D15: 523 - Bérjárulékok | E15: 461124. Szociális hozzájárulási adó | F15: 26000
A16: KR14 | B16: 45991 | C16: BB-Bruttó bér november | D16: 521. Bérköltség | E16: 4581. Jövedelem elsz. számla | F16: 150000
A17: KR15 | B17: 45991 | C17: BB-SZJA november | D17: 4581. Jövedelem elsz. számla | E17: 461103. SZJA | F17: 22500
A18: KR16 | B18: 45991 | C18: BB-TB november | D18: 4581. Jövedelem elsz. számla | E18: 461125. Társadalombiztosítási járulék | F18: 27750
A19: KR17 | B19: 45991 | C19: BB-SZOCHO november | D19: 523 - Bérjárulékok | E19: 461124. Szociális hozzájárulási adó | F19: 19500
A20: KR18 | B20: 45991 | C20: CC-Bruttó bér november | D20: 521. Bérköltség | E20: 4581. Jövedelem elsz. számla | F20: 150000
A21: KR19 | B21: 45991 | C21: CC-SZJA november | D21: 4581. Jövedelem elsz. számla | E21: 461103. SZJA | F21: 22500
A22: KR20 | B22: 45991 | C22: CC-TB november | D22: 4581. Jövedelem elsz. számla | E22: 461125. Társadalombiztosítási járulék | F22: 27750
A23: KR21 | B23: 45991 | C23: CC-SZOCHO november | D23: 523 - Bérjárulékok | E23: 461124. Szociális hozzájárulási adó | F23: 19500
... A34: KR32 | B34: 45952 | C34: TAO kötelezettség | D34: 89. Nyereséget terhelő adó | E34: 461101. TAO | F34: 280000

Sheet Tagi kölcsön analitika
A1: Tagi Kölcsön Analitika
A2: Bizonylat sorszáma | B2: Kölcsönadó | C2: Dátum | D2: Összeg | E2: Kamatláb | F2: Elszámolás napja | G2: Kamatösszege | H2: Kamat SZJA terhe | I2: Kamat SZOCHO terhe | J2: Összes kifizetés | K2: Munkavállalónak fizetve nettóban
A3: PB05 | B3: Alfonz Aladár | C3: 45933 | D3: 90380 | E3: ='Időbeli elhatárolás analitika'!$O$2*2 -> 0.125
A4: PB06 | B4: Alfonz Aladár | C4: 45950 | D4: 1397 | E4: ='Időbeli elhatárolás analitika'!$O$2*2 -> 0.125
A5: B001 | B5: Bélapátfalvi Bendegúz | C5: 45947 | D5: 300000 | E5: ='Időbeli elhatárolás analitika'!$O$2*2 -> 0.125 | F5: 45993 | G5: =D5*(E5/365*(F5-C5+1)) -> 4828.7671 | H5: =G5*0.15 -> 724.31507 | I5: =G5*0.13 -> 627.73973 | J5: =G5+I5+D5 -> 305456.51 | K5: =D5+G5-H5 -> 304104.45

Sheet Időbeli elhatárolás analitika
A1: Elhatárolás analitika
A2: Beszámoló | B2: Bizonylatszám | C2: Tétel | D2: Partner neve | E2: Aktív/Passzív időbeli elhatárolás | F2: Költség/Ráfordítás/Bevétel | G2: Számla kelte | H2: Időszak kezdete | I2: Elhatárolás kezdete | J2: Elhatárolás vége | K2: Elszámolás alapja | L2: Elhatárolás összege | N2: jegybanki alap kamat | O2: 0.0625
A3: Előtársaság | B3: UZ119/2025 | C3: Reklám felületbérlés | D3: Group Media Ügynökség | E3: Aktív | F3: Költség | G3: 45938 | H3: 45939 | I3: 45953 | J3: 45968 | K3: 240000 | L3: =(J3-I3+1)/(J3-H3+1)*K3 -> 128000
A4: Előtársaság | B4: JJ8821/2025 | C4: WebHosting szolgáltatás | D4: StarSite Group Kft. | E4: Aktív | F4: Költség | G4: 45943 | H4: 45943 | I4: 45953 | J4: 46307 | K4: 120000 | L4: =(J4-I4+1)/(J4-H4+1)*K4 -> 116712.33
A5: Előtársaság | B5: B001 | C5: Bankköltségek | D5: PénzGyűjtő Bank | E5: Passzív | F5: Költség | G5: 45961 | H5: 45933 | I5: 45953 | J5: 45961 | K5: =5414+3076 -> 8490 | L5: =K5-(J5-I5+1)/(J5-H5+1)*K5 -> 5855.1724
A6: Előtársaság | B6: B001 | C6: Elhatárolt kamat | D6: PénzGyűjtő Bank | E6: Aktív | F6: Bevétel | G6: 45961 | H6: 45938 | I6: 45953 | J6: 45961 | K6: 7890 | L6: =K6-(J6-I6+1)/(J6-H6+1)*K6 -> 4931.25
A7: Előtársaság | B7: PB05 | C7: Tagi kölcsön | D7: Belső | E7: Passzív | F7: Ráfordítás | G7: 45950 | H7: 45950 | I7: 45953 | J7: 45953 | K7: =90380*O2*2 -> 11297.5 | L7: =K7*(I7-H7+1)/365 -> 123.80822
A8: Előtársaság | B8: PB06 | C8: Tagi kölcsön | D8: Belső | E8: Passzív | F8: Ráfordítás | G8: 45951 | H8: 45951 | I8: 45953 | J8: 45953 | K8: =1397*O2*2 -> 174.625 | L8: =K8*(I8-H8+1)/365 -> 1.435274
A9: Előtársaság | B9: B001 | C9: Tagi kölcsön | D9: Belső | E9: Passzív | F9: Ráfordítás | G9: 45947 | H9: 45947 | I9: 45953 | J9: 45953 | K9: =300000*O2*2 -> 37500 | L9: =K9*(I9-H9+1)/365 -> 719.17808

Sheet Tárgyi eszköz analitika
A1: Bizonylatszám | B1: HY986/2025 | C1: Főkönyvi szám | F1: 1232 | G1: Értékcsökkenés paraméterek: 200 EFt alatti értékű eszköz | M1: Nettó érték
A2: Azonosító adatok
A3: Dátum | B3: Bizonylatszám | C3: Megnevezés | D3: Bruttó érték | G3: Terv szerinti értékcsökkenés | J3: Terven felüli értékcsökkenés
D4: Növekedés | E4: Csökkenés | F4: Egyenleg | G4: Növekedés | H4: Csökkenés | I4: Egyenleg | J4: Növekedés | K4: Csökkenés | L4: Egyenleg
A5: 45951 | B5: KR08 | C5: Aktiválás | D5: 82760 | F5: =D5-E5 -> 82760 | I5: =G5-H5 -> 0 | L5: =J5-K5 -> 0 | M5: =F5-I5-L5 -> 82760
A6: 45951 | B6: KR09 | C6: Értékcsökkenés | F6: =F5+D6-E6 -> 82760 | G6: 82760 | I6: =I5+G6-H6 -> 82760 | L6: =L5+J6-K6 -> 0 | M6: =F6-I6-L6 -> 0
A19: Bizonylatszám | B19: HZ-7127 | C19: Főkönyvi szám | F19: 1231 | G19: Értékcsökkenés paraméterek: 2 év | M19: Nettó érték
A20: Azonosító adatok
A21: Dátum | B21: Bizonylatszám | C21: Megnevezés | D21: Bruttó érték | G21: Terv szerinti értékcsökkenés | J21: Terven felüli értékcsökkenés
D22: Növekedés | E22: Csökkenés | F22: Egyenleg | G22: Növekedés | H22: Csökkenés | I22: Egyenleg | J22: Növekedés | K22: Csökkenés | L22: Egyenleg
A23: 45975 | B23: KR33 | C23: Aktiválás | D23: =307721/1.27+28702/1.27 -> 264900 | F23: =D23-E23 -> 264900 | I23: =G23-H23 -> 0 | L23: =J23-K23 -> 0 | M23: =F23-I23-L23 -> 264900
A33: Bizonylatszám | B33: HZ-7127 | C33: Főkönyvi szám | F33: 1231 | G33: Értékcsökkenés paraméterek: 5 év | M33: Nettó érték
A34: Azonosító adatok
A35: Dátum | B35: Bizonylatszám | C35: Megnevezés | D35: Bruttó érték | G35: Terv szerinti értékcsökkenés | J35: Terven felüli értékcsökkenés
D36: Növekedés | E36: Csökkenés | F36: Egyenleg | G36: Növekedés | H36: Csökkenés | I36: Egyenleg | J36: Növekedés | K36: Csökkenés | L36: Egyenleg
A37: 45975 | B37: KR34 | C37: Aktiválás | D37: =71501/1.27 -> 56300 | F37: =D37-E37 -> 56300 | I37: =G37-H37 -> 0 | L37: =J37-K37 -> 0 | M37: =F37-I37-L37 -> 56300
A38: 45975 | B38: KR35 | C38: Értékcsökkenés | F38: =F37+D38-E38 -> 56300 | G38: 56300 | I38: =I37+G38-H38 -> 56300 | L38: =L37+J38-K38 -> 0 | M38: =F38-I38-L38 -> 0
A47: Bizonylatszám | B47: HT556/2025. | C47: Főkönyvi szám | F47: 1221 | G47: Értékcsökkenés paraméterek: 5 év | M47: Nettó érték
A48: Azonosító adatok
A49: Dátum | B49: Bizonylatszám | C49: Megnevezés | D49: Bruttó érték | G49: Terv szerinti értékcsökkenés | J49: Terven felüli értékcsökkenés
D50: Növekedés | E50: Csökkenés | F50: Egyenleg | G50: Növekedés | H50: Csökkenés | I50: Egyenleg | J50: Növekedés | K50: Csökkenés | L50: Egyenleg
A51: 45975 | B51: KR36 | C51: Aktiválás | D51: =1778000+22000 -> 1800000 | F51: =D51-E51 -> 1800000 | I51: =G51-H51 -> 0 | L51: =J51-K51 -> 0 | M51: =F51-I51-L51 -> 1800000
A52: 45996 | B52: KR37 | C52: Ráaktiválás | D52: =382.08*450 -> 171936 | F52: =F51+D52-E52 -> 1971936 | I52: =G52-H52 -> 0 | L52: =J52-K52 -> 0 | M52: =F52-I52-L52 -> 1971936
A53: 46006 | B53: KR38 | C53: Ráaktiválás | D53: 101600 | F53: =F52+D53-E53 -> 2073536 | I53: =G53-H53 -> 0 | L53: =J53-K53 -> 0 | M53: =F53-I53-L53 -> 2073536
A54: 46009 | B54: KR39 | C54: Terven felüli écs | F54: =F53+D54-E54 -> 2073536 | I54: =G54-H54 -> 0 | J54: =F54-1600000 -> 473536 | L54: =J54-K54 -> 473536 | M54: =F54-I54-L54 -> 1600000

Sheet Béranalitika
A1: Béranalitika
A2: Hónap | B2: Munkavállaló | C2: Bruttó Bér | D2: SZJA | E2: TB | F2: Szocho | G2: Nettó bér | H2: Munkáltatói teher
A3: November | B3: Alfonz Aladár | C3: 200000 | D3: =$C$3*0.15 -> 30000 | E3: =$C$3*0.185 -> 37000 | F3: =$C$3*0.13 -> 26000 | G3: =C3-D3-E3 -> 133000 | H3: =C3+F3 -> 226000
A4: November | B4: Bélapátfalvi Bendegúz | C4: =150000 -> 150000 | D4: =$C4*0.15 -> 22500 | E4: =$C4*0.185 -> 27750 | F4: =$C4*0.13 -> 19500 | G4: =C4-D4-E4 -> 99750 | H4: =C4+F4 -> 169500
A5: November | B5: Cirmai Cecília | C5: 150000 | D5: =$C5*0.15 -> 22500 | E5: =$C5*0.185 -> 27750 | F5: =$C5*0.13 -> 19500 | G5: =C5-D5-E5 -> 99750 | H5: =C5+F5 -> 169500
A6: November | B6: Hrabovszki András | C6: 150000 | D6: =$C6*0.15 -> 22500 | E6: =$C6*0.185 -> 27750 | F6: =$C6*0.13 -> 19500 | G6: =C6-D6-E6 -> 99750 | H6: =C6+F6 -> 169500
D8: =SUM(D3:D6) -> 97500 | E8: =SUM(E3:E6) -> 120250 | F8: =SUM(F3:F6) -> 84500

Sheet AFA_Előtársaság 
C1: 2565 | F1: ÁFA BEVALLÁS
B3: I.
C5: Adózó azonosítószáma: | E5: 12457899-2-42
C7: Adózó neve: | E7: Prompt Integra Kft.
C9: Ügyintéző neve: | E9: Hrabovszki András | H9: Telefonszáma: | I9: 06200315203
C11: Bevallási időszak: | E11: Kezdete: | H11: Vége:
E12: 45933 | H12: 45952
C14: Adózó belföldi pénzforgalmi vagy fizetési számlaszáma:
E15: 15151515-23232323-46464646 | G15: 15151515-23232323-46464646
C17: Felelősségem tudatában kijelentem, hogy a bevallásban közölt adatok a valóságnak megfelelnek:
C19: Budapest | F19: 45981 | I19: Alfonz Aladár
D20: helység | F20: kelt | I20: aláírás
B23: II.
D25: Fizetendő általános forgalmi adó | I25: eFt
H26: Az adó alapja | I26: Az adó összege
C27: 01 | D27: 5%-os kulcs alá tartozó értékesítés | K27: =IF(ABS(H27*0.05-I27)>0.5,"HIBA!","")
C28: 02 | D28: 18%-os kulcs alá tartozó értékesítés | K28: =IF(ABS(H28*0.18-I28)>0.5,"HIBA!","")
C29: 03 | D29: 27%-os kulcs alá tartozó értékesítés | H29: 3600 | I29: ='ÁFA analitika'!J10/1000 -> 972 | K29: =IF(ABS(H29*0.27-I29)>0.5,"HIBA!","")
C30: 04 | D30: Adómentes értékesítés | I30: 0
C31: 05 | D31: Közösségen belülről történő termékbeszerzés
C32: 06 | D32: Különleges eljárással megállapított adó
C33: 07 | D33: Saját vállalkozáson belül végzett beruházás után fizetendő adó:
C34: 08 | D34: Egyéb
C35: 09 | D35: Összesen: | H35: =SUM(H27:H34) -> 3600 | I35: =SUM(I27:I34) -> 972
C36: 10 | D36: -ebből: tárgyi eszköz értékesítés
C37: 11 | D37: -ebből: apport értékesítés
B40: III.
D42: Beszerzést terhelő, előzetesen felszámított, levonható általános forgalmi adó | I42: eFt
H43: Az adó alapja | I43: Az adó összege
C44: 12 | D44: Adómentes belföldi termékbeszerzés | I44: 0
C45: 13 | D45: 5%-os kulcs alá tartozó belföldi termékbeszerzés, szolgáltatás | K45: =IF(ABS(H45*0.05-I45)>0.5,"HIBA!","")
C46: 14 | D46: 18%-os kulcs alá tartozó belföldi termékbeszerzés, szolgáltatás | K46: =IF(ABS(H46*0.18-I46)>0.5,"HIBA!","")
C47: 15 | D47: 27%-os kulcs alá tartozó belföldi termékbeszerzés, szolgáltatás | H47: 657 | I47: 177 | K47: =IF(ABS(H47*0.27-I47)>0.5,"HIBA!","")
C48: 16 | D48: Arányosítás alkalmazásával levonható adórész
C49: 17 | D49: Saját vállalkozáson belül végzett beruházás után:
C50: 18 | D50: Közösségen belülről történő termékbeszerzés
C51: 19 | D51: Egyéb
C52: 20 | D52: Összesen: | H52: =SUM(H44:H51) -> 657 | I52: =SUM(I44:I51) -> 177
C53: 21 | D53: -ebből: tárgyi eszköz beszerzés után levonható adó | H53: 83 | I53: 22
C54: 22 | D54: -ebből: apport beszerzés után levonható adó
...

Sheet Áfa_10 
C1: 2565 | F1: ÁFA BEVALLÁS
B3: I.
C5: Adózó azonosítószáma: | E5: 12457899-2-42
C7: Adózó neve: | E7: Prompt Integra Kft.
C9: Ügyintéző neve: | E9: Hrabovszki András | H9: Telefonszáma: | I9: 06200315203
C11: Bevallási időszak: | E11: Kezdete: | H11: Vége:
E12: 45953 | H12: 45961
C14: Adózó belföldi pénzforgalmi vagy fizetési számlaszáma:
E15: 15151515-23232323-46464646 | G15: 15151515-23232323-46464646
C17: Felelősségem tudatában kijelentem, hogy a bevallásban közölt adatok a valóságnak megfelelnek:
C19: Budapest | F19: 45981 | I19: Alfonz Aladár
D20: helység | F20: kelt | I20: aláírás
B23: II.
D25: Fizetendő általános forgalmi adó | I25: eFt
H26: Az adó alapja | I26: Az adó összege
C27: 01 | D27: 5%-os kulcs alá tartozó értékesítés | K27: =IF(ABS(H27*0.05-I27)>0.5,"HIBA!","")
C28: 02 | D28: 18%-os kulcs alá tartozó értékesítés | K28: =IF(ABS(H28*0.18-I28)>0.5,"HIBA!","")
C29: 03 | D29: 27%-os kulcs alá tartozó értékesítés | H29: 315 | I29: 85 | K29: =IF(ABS(H29*0.27-I29)>0.5,"HIBA!","")
C30: 04 | D30: Adómentes értékesítés | I30: 0
C31: 05 | D31: Közösségen belülről történő termékbeszerzés
C32: 06 | D32: Különleges eljárással megállapított adó
C33: 07 | D33: Saját vállalkozáson belül végzett beruházás után fizetendő adó:
C34: 08 | D34: Egyéb
C35: 09 | D35: Összesen: | H35: =SUM(H27:H34) -> 315 | I35: =SUM(I27:I34) -> 85
C36: 10 | D36: -ebből: tárgyi eszköz értékesítés
C37: 11 | D37: -ebből: apport értékesítés
B40: III.
D42: Beszerzést terhelő, előzetesen felszámított, levonható általános forgalmi adó | I42: eFt
H43: Az adó alapja | I43: Az adó összege
C44: 12 | D44: Adómentes belföldi termékbeszerzés | I44: 0
C45: 13 | D45: 5%-os kulcs alá tartozó belföldi termékbeszerzés, szolgáltatás | K45: =IF(ABS(H45*0.05-I45)>0.5,"HIBA!","")
C46: 14 | D46: 18%-os kulcs alá tartozó belföldi termékbeszerzés, szolgáltatás | K46: =IF(ABS(H46*0.18-I46)>0.5,"HIBA!","")
C47: 15 | D47: 27%-os kulcs alá tartozó belföldi termékbeszerzés, szolgáltatás | H47: 321 | I47: 87 | K47: =IF(ABS(H47*0.27-I47)>0.5,"HIBA!","")
C48: 16 | D48: Arányosítás alkalmazásával levonható adórész
C49: 17 | D49: Saját vállalkozáson belül végzett beruházás után:
C50: 18 | D50: Közösségen belülről történő termékbeszerzés
C51: 19 | D51: Egyéb
C52: 20 | D52: Összesen: | H52: =SUM(H44:H51) -> 321 | I52: =SUM(I44:I51) -> 87
C53: 21 | D53: -ebből: tárgyi eszköz beszerzés után levonható adó
C54: 22 | D54: -ebből: apport beszerzés után levonható adó
...

Sheet BÉR_11
C1: 2508A KIFIZETÉSEKKEL, JUTTATÁSOKKAL ÖSSZEFÜGGŐ ADÓRÓL,
C2: JÁRULÉKOKRÓL ÉS EGYÉB ADATOKRÓL, VALAMINT A SZAKKÉPZÉSI HOZZÁJÁRULÁSRÓL
B3: I.
C5: Adózó azonosítószáma: | E5: 12457899-2-42
C7: Adózó neve: | E7: Prompt Integra Kft.
C9: Székhelye: | E9: 1058 Budapest, Fővám tér 8.
C11: Ügyintéző neve: | E11: Hrabovszki András | H11: Telefonszáma: | I11: 06200315203
C13: Bevallási időszak: | E13: Kezdete: | H13: Vége:
E14: 45962 | H14: 45991
C16: Bevallásban érintett természetes személyek száma: | F16: 4
C19: Felelősségem tudatában kijelentem, hogy a bevallásban közölt adatok a valóságnak megfelelnek:
C21: Budapest | F21: 46003 | I21: Alfonz Aladár
D22: helység | F22: kelt | I22: aláírás
B25: 2508A-01 Személyi jövedelemadó
I27: eFt
I28: Az adó összege
C29: 01 | D29: Személyi jövedelemadó összesen | H29: 103 | I29: =SUM(I30:I34) -> 98
C30: 02 | D30: egyes meghatározott juttatásokat terhelő | H30: 103 | I30: 98
C31: 03 | D31: béren kívüli juttatásokat terhelő | H31: 103
C32: 04 | D32: önkormányzat által fizetendő 15%, illetve 8%-os adó | H32: 103
C33: 05 | D33: reprezentáció, üzleti ajándék után fizetendő adó | H33: 103
C34: 06 | D34: más, kifizetőt terhelő adó | H34: 103
C35: 07 | D35: Természetes személytől levont személyi jövedelemadó összesen: | H35: 290 | I35: =+SUM(I36:I41) -> 0
C36: 08 | D36: Külföldi illetőségű term. személy osztalékból származó jövedelméből levont adó | H36: 290
C37: 09 | D37: kamatjövedelmet terhelő adó | H37: 290
C38: 10 | D38: fémkereskedelmi engedélyköteles anyag átruházására tekintettel levont adó | H38: 290
C39: 11 | D39: vadon gyűjtött termék, termény értékesítésére levont adó | H39: 290
C40: 12 | D40: a társasházaknak kifizetett jövedelemből levont adó | H40: 290
C41: 13 | D41: Stabilitás Megtakarítási Számláról származó jövedelemből levont adó | H41: 290
C42: 14 | D42: Egészségügyi hozzájárulás | H42: 152 | I42: =+I43+I44 -> 0
C43: 15 | D43: 14%-os mértékű egészségügyi hozzájárulás | H43: 152
C44: 16 | D44: 19,5%-os mértékű egészségügyi hozzájárulás | H44: 152
B47: 2508A-03 Magánszemélyenként megállapított adókötelezettségek
I49: eFt
C50: Személyi jövedelemadó | I50: Az adó összege
C51: 70 | D51: Az összevont adóalapt terhelő, levont adóelőleg összege | I51: 98
C52: 71 | D52: A külön adózó jövedelmek adóalapját terhelő adó összege
C53: 72 | D53: Az osztalékelőleget terhelő adó összege
C54: 73 | D54: Személyi jövedelemadó kötelezettség összesen | I54: =+SUM(I51:I53) -> 98
C56: Szociális hozzájárulási adó | I56: Az adó összege
...

Sheet HIPA_Előtársaság
B1: 25HIPA | G1: Helyi iparűzési adó bevallás
B3: Főlap | X3: 1. Éves bevallás
X4: 2. Záró bevallás
C5: I. Bevallás jellege: | E5: 3. Előtársasági bevallás | X5: 3. Előtársasági bevallás
X6: 4. Naptári évtől eltérő üzleti évet választó adózó bevallása
C7: II. Bevallott időszak: | E7: Kezdete: | G7: 45933 | M7: Vége: | O7: 45952 | X7: 5. Év közben kezdő adózó bevallása
X8: 6. Naptári évtől eltérő üzleti évet választó adózó áttérésének évéről készült évközi bevallása
C9: III. A záró bevallás benyújtásának oka: | X9: 8. állandó jellegű iparűzési tevékenységgé váló tevékenység után benyújtott bevallás
X10: 9. A kisadózó vállalkozás tételes adójának alanyaként benyújtott bevallás
C11: IV. Bevallásban szereplő betétlapok | E11: x | F11: A | H11: B | J11: C | L11: D | N11: E | P11: F | R11: G | T11: H | X11: 10. A Htv. 39/E. §-a szerint mentes adóalany bevallása
X12: 11. Önellenőrzés
C13: V. Adóalany
X14: 1. Felszámolás
D15: 1. Az adóalany neve: | E15: Prompt Integra Kft. | X15: 1. Felszámolás
X16: 1. Felszámolás
D17: 2. Az adóalany azonosítója: | E17: 12457899-2-42 | X17: 1. Felszámolás
X18: 2. Végelszámolás
D19: 3. Székhelye: | E19: 1058 Budapest, Fővám tér 8. | X19: 3. Átalakulás
X20: 4. A tevékenység saját elhatározásból történő megszüntetése
D21: 4. A bevallást kitöltő neve: | E21: Hrabovszki András | X21: 5. Hatósági megszűntetés
X22: 6. Naptári évtől eltérő üzleti évet választó adózó áttérésének évéről készült évközi bevallása
C23: VI. Az adó alapjának egyszerűsített módját választók nyilatkozata: | X23: 8. állandó jellegű iparűzési tevékenységgé váló tevékenység után benyújtott bevallás
X24: 9. Egyszerűsített vállalkozói adóalanyiság megszűnése
D25: Az adóévre az adóalap egyszerűsített megállapítási módját választom: | X25: 10. Egyéni vállalkozói tevékenység szüneteltetése
X26: 11. A kisadózó vállalkozások tételes adójában az adóalanyiság év közben való keletkezése
X27: 12. A kisadózó vállalkozások tételes adójában az adóalanyiság megszűnése
B28: VII. Adó | X28: 13. A kisvállalati adóban az adóalanyiság megszűnése
X29: 14. A települési önkormányzat adórendeletének hatályon kívül helyezése
C30: 1. Htv. szerinti - vállalkozási szintű - éves nettó árbevétel (részletezése külön lapon található) | R30: =+R100 -> 3600000 | X30: 15. Egyéb
C32: 2. Eladott áruk beszerzési értékének, közvetített szolgáltatások értékének figyelembe vehető együttes összege | W32: =IF(ABS(T30*0.05-U30)>0.5,"HIBA!","")
W33: =IF(ABS(T31*0.18-U31)>0.5,"HIBA!","")
C34: 3. Az alvállalkozói teljesítések értéke | W34: =IF(ABS(T32*0.27-U32)>0.5,"HIBA!","") | X34: a) a személy jövedelemadóról szóló törvény szerinti átalányadózóként
X35: b) az egyszerűsített vállalkozói adó alanyaként
C36: 4. Anyagköltség | R36: 5468 | X36: c) az adóévben 8 millió forintot meg nem haladó nettó árbevételű adóalanyként
X37: d) a kisvállalati adó hatálya alá tartozó adóalanyként
C38: 5. Alapkutatás, alkalmazott kutatás, kísérleti fejlesztés adóévben elszámolt közvetlen költsége
C40: 6. Htv. szerinti – vállalkozási szintű – adóalap [1-(2+3+4+5)] | R40: =+R30-(R32+R34+R36+R38) -> 3594532
C42: 7. A foglalkoztatás növeléséhez kapcsolódó adóalap-mentesség
C44: 8. A foglalkoztatás csökkentéséhez kapcsolódó adóalap-növekmény
C46: 9. Mentességekkel korrigált Htv. szerinti – vállalkozási szintű – adóalap [6-7+8] | R46: =+R40+R42-R44 -> 3594532
...

Sheet Főkönyvi kivonat_HIPA előtt
A1: Főkönyvi kivonat
A2: Prompt Integra Kft.
A3: Időszak: 20251003 - 20251022
C5: Forgalom | E5: Egyenleg
A6: Fők.szám | B6: Megnevezés | C6: Tartozik | D6: Követel | E6: Tartozik | F6: Követel
A7: 1231 | B7: Egyéb berendezések, felszerelések, járművek bruttó értéke | C7: 82760 | D7: 0 | E7: 82760 | F7: 0
A8: 1232 | B8: Egyéb berendezések, felszerelések, járművek terv sz. értékcsökkenése | C8: 0 | D8: 82760 | E8: 0 | F8: 82760
A9: 1251 | B9: Beruházások, felújítások bruttó értéke | C9: 82760 | D9: 82760 | E9: 0 | F9: 0
A10: 1 | B10: Befektetett eszközök | C10: 165520 | D10: 165520 | E10: 82760 | F10: 82760
A11: 3111 | B11: Követelések áruszállításból és szolgáltatásból (vevők); nem devizás | C11: 4572000 | D11: 0 | E11: 4572000 | F11: 0
A12: 381 | B12: Pénztár, csekkek | C12: 1841782 | D12: 1796887 | E12: 44895 | F12: 0
A13: 3821 | B13: Elszámolási betét (bank) | C13: 1900000 | D13: 1807200 | E13: 92800 | F13: 0
A14: 38291 | B14: Átvezetés számla bank-pénztár, pénztár-bank | C14: 1750000 | D14: 1750000 | E14: 0 | F14: 0
A15: 38292 | B15: Átvezetés számla bank-bank | C15: 1200000 | D15: 0 | E15: 1200000 | F15: 0
A16: 391 | B16: Bevételek aktív időbeli elhatárolása | C16: 4931 | D16: 0 | E16: 4931 | F16: 0
A17: 392 | B17: Költségek, ráfordítások aktív időbeli elhatárolása | C17: 244712 | D17: 0 | E17: 244712 | F17: 0
A18: 3 | B18: Követelések, értékp., pénzeszk. és akt.id. elh. | C18: 11513425 | D18: 5354087 | E18: 6159338 | F18: 0
... A40: 0..9 | B40: Mindösszesen | C40: 17333065 | D40: 17333065 | E40: 8267512 | F40: 8267512

Sheet TAO_Előtársaság
C1: 2529 | F1: TÁRSASÁGI ADÓ BEVALLÁS
B3: I.
C5: Adózó azonosítószáma: | E5: 12457899-2-42
C7: Adózó neve: | E7: Prompt Integra Kft.
C9: Székhelye: | E9: 1058 Budapest, Fővám tér 8.
C11: Ügyintéző neve: | E11: Hrabovszki András | H11: Telefonszáma:
C13: Bevallási időszak: | E13: Kezdete: | H13: Vége:
E14: 45933 | H14: 45952
C16: Adózó belföldi pénzforgalmi vagy fizetési számlaszáma:
E17: 15151515-23232323-46464646
C19: Felelősségem tudatában kijelentem, hogy a bevallásban közölt adatok a valóságnak megfelelnek:
C21: Budapest | F21: 46009 | I21: Alfonz Aladár
D22: helység | F22: kelt | I22: aláírás
B25: 2529-01 Társasági adó bevallása
I27: eFt
I28: Az adó összege
C29: 01 | D29: Adózás előtti eredmény | I29: =+I78 -> 3108
C30: 02 | D30: Adózás előtti eredményt csökkentő tételek összesen: | I30: =+I48 -> 83
C31: 03 | D31: Adózás előtti eredményt növelő tételek összesen: | I31: =+I62 -> 83
C32: 04 | D32: Adóalap: | I32: =+I29-I30+I31 -> 3108
C33: 05 | D33: Társasági adó: | I33: =+MAX(ROUND(I32*9%,0),0) -> 280
C34: 06 | D34: Adókedvezmények:
C35: 07 | D35: Fizetendő adó: | I35: =+I33-I34 -> 280
B38: 2529-03 Adózás előtti eredményt csökkentő jogcímek
I40: eFt
I41: Az adó összege
C42: 08 | D42: Az előző évek elhatárolt veszteségéből (negatív adóalapjából) az adóévben leírt összeg:
C43: 09 | D43: A várható kötelezettségekre és jövőbeni költségekre képzett céltartalék bevételként elszámolt része
C44: 10 | D44: A terven felüli értékcsökkenés adóévben visszaírt összege | I44: 83
C45: 11 | D45: Az adótörvény szerint figyelembe vett értékcsökkenési leírás összege
C46: 12 | D46: Kapott, járó, bevételként elszámolt osztalék és részesedés
C47: 13 | D47: Új eszközök üzembe helyezése érdekében elszámolt adóévi beruházások értéke
C48: 14 | D48: Összesen: | I48: =SUM(I42:I47) -> 83
B51: 2529-04 Adózás előtti eredményt növelő jogcímek
I53: eFt
I54: Az adó összege
C55: 15 | D55: Várható kötelezettségekre, és a jövőbeni költségekre képzett céltartalék, céltartalékot növelő összeg
C56: 16 | D56: Számviteli törvény szerint elszámolt terv szerinti értékcsökkenés összege | I56: 83
C57: 17 | D57: Nem a vállalkozási, bevételszerző tevékenységgel kapcsolatos költségek, ráfordítások
C58: 18 | D58: Jogerős határozatban megállapított bírság, az Art. és a Tb-törvények szerinti jogkövetkezmények
...

Sheet Főkönyvi kivonat_TAO előtt
A1: Főkönyvi kivonat
A2: Prompt Integra Kft.
A3: Időszak: 20251003 - 20251022
C5: Forgalom | E5: Egyenleg
A6: Fők.szám | B6: Megnevezés | C6: Tartozik | D6: Követel | E6: Tartozik | F6: Követel
A7: 1231 | B7: Egyéb berendezések, felszerelések, járművek bruttó értéke | C7: 82760 | D7: 0 | E7: 82760 | F7: 0
A8: 1232 | B8: Egyéb berendezések, felszerelések, járművek terv sz. értékcsökkenése | C8: 0 | D8: 82760 | E8: 0 | F8: 82760
A9: 1251 | B9: Beruházások, felújítások bruttó értéke | C9: 82760 | D9: 82760 | E9: 0 | F9: 0
A10: 1 | B10: Befektetett eszközök | C10: 165520 | D10: 165520 | E10: 82760 | F10: 82760
A11: 3111 | B11: Követelések áruszállításból és szolgáltatásból (vevők); nem devizás | C11: 4572000 | D11: 0 | E11: 4572000 | F11: 0
A12: 381 | B12: Pénztár, csekkek | C12: 1841782 | D12: 1796887 | E12: 44895 | F12: 0
A13: 3821 | B13: Elszámolási betét (bank) | C13: 1900000 | D13: 1807200 | E13: 92800 | F13: 0
A14: 38291 | B14: Átvezetés számla bank-pénztár, pénztár-bank | C14: 1750000 | D14: 1750000 | E14: 0 | F14: 0
A15: 38292 | B15: Átvezetés számla bank-bank | C15: 1200000 | D15: 0 | E15: 1200000 | F15: 0
A16: 391 | B16: Bevételek aktív időbeli elhatárolása | C16: 4931 | D16: 0 | E16: 4931 | F16: 0
A17: 392 | B17: Költségek, ráfordítások aktív időbeli elhatárolása | C17: 244712 | D17: 0 | E17: 244712 | F17: 0
A18: 3 | B18: Követelések, értékp., pénzeszk. és akt.id. elh. | C18: 11513425 | D18: 5354087 | E18: 6159338 | F18: 0
... A42: 0..9 | B42: Mindösszesen | C42: 17404956 | D42: 17404956 | E42: 8339403 | F42: 8339403

Sheet Áfa analitika
A1: Áfa analitika
A2: Sorszám | B2: Fizetendő/Levonható | C2: Partner | D2: Számlaszám | E2: Számla kelte | F2: Nettó érték | G2: Áfa kulcs | H2: Áfa összege | I2: Bruttó érték
